Workbook

Sheet CSV Template
A1: ID | B1: MARK | C1: PN | D1: MANUFACTURER | E1: MANUFACTURER PART # | F1: DESCRIPTION | G1: QTY | H1: W | I1: H | J1: D
A2: 1 | B2: SCB1 | C2: SPCB=SU201M-C13 | D2: ABB | E2: SU201M-C13 | F2: MINIATURE CIRCUIT BREAKER, 230 VAC, 13A, 1 POLE, C-CURVE TRIP | G2: 1 | H2: =VLOOKUP($C2,'Size DB'!$C$2:$J$2000,6,0) -> 17.5 | I2: =VLOOKUP($C2,'Size DB'!$C$2:$J$2000,7,0) -> 111 | J2: =VLOOKUP($C2,'Size DB'!$C$2:$J$2000,8,0) -> 0
A3: 2 | B3: SCB2, SCB3 | C3: SPCB=SU201M-C4 | D3: ABB | E3: SU201M-C4 | F3: MINIATURE CIRCUIT BREAKER, 230 VAC, 4A, 1 POLE, C-CURVE TRIP | G3: 2 | H3: =VLOOKUP($C3,'Size DB'!$C$2:$J$2000,6,0) -> 17.5 | I3: =VLOOKUP($C3,'Size DB'!$C$2:$J$2000,7,0) -> 111 | J3: =VLOOKUP($C3,'Size DB'!$C$2:$J$2000,8,0) -> 0
A4: 3 | B4: N7 | C4: ELCO=ACUVIM-AXM-WEB2 | D4: Accuenergy | E4: AXM-WEB2 | F4: MULTIFUNCTION POWER AND ENERGY METER COMMUNICATION MODULE | G4: 1 | H4: =VLOOKUP($C4,'Size DB'!$C$2:$J$2000,6,0) -> 0 | I4: =VLOOKUP($C4,'Size DB'!$C$2:$J$2000,7,0) -> 0 | J4: =VLOOKUP($C4,'Size DB'!$C$2:$J$2000,8,0) -> 0
A5: 4 | B5: N7 | C5: ELCO=ACUVIM-CL-M-5A-P1V4 | D5: Accuenergy | E5: Acuvim-CL-M-5A-P1V4 | F5: MULTIFUNCTION POWER AND ENERGY METER, 1-5A, 100-415 VAC | G5: 1 | H5: =VLOOKUP($C5,'Size DB'!$C$2:$J$2000,6,0) -> 96 | I5: =VLOOKUP($C5,'Size DB'!$C$2:$J$2000,7,0) -> 96 | J5: =VLOOKUP($C5,'Size DB'!$C$2:$J$2000,8,0) -> 0
A6: 5 | B6: CT1, CT2, CT3 | C6: INCT=2031-1001 | D6: Accuenergy | E6: AcuCT-2031-1000:5 | F6: SPLIT-CORE CURRENT TRANSFORMER, 1000:5A | G6: 3 | H6: =VLOOKUP($C6,'Size DB'!$C$2:$J$2000,6,0) -> 114 | I6: =VLOOKUP($C6,'Size DB'!$C$2:$J$2000,7,0) -> 145 | J6: =VLOOKUP($C6,'Size DB'!$C$2:$J$2000,8,0) -> 0
A7: 6 | B7: N2 | C7: ELTO=TPC-107WX | D7: Advantech Corp | E7: TPC-107WX-N32YA | F7: TOUCH SCREEN HMI, 7" SCREEN, 2GB RAM, 16GB STORAGE, -30C TO 70C | G7: 1 | H7: =VLOOKUP($C7,'Size DB'!$C$2:$J$2000,6,0) -> 205 | I7: =VLOOKUP($C7,'Size DB'!$C$2:$J$2000,7,0) -> 146.92 | J7: =VLOOKUP($C7,'Size DB'!$C$2:$J$2000,8,0) -> 0
A8: 7 | B8: S2, S3 | C8: ELSE=PS21L-NS11R1-T00 | D8: Carlo Gavazzi | E8: PS21L-NS11R1-T00 | F8: SWITCH LIMIT, ROLLER LEVER, SPST-NO, SPST-NC, 10A | G8: 2 | H8: =VLOOKUP($C8,'Size DB'!$C$2:$J$2000,6,0) -> 0 | I8: =VLOOKUP($C8,'Size DB'!$C$2:$J$2000,7,0) -> 0 | J8: =VLOOKUP($C8,'Size DB'!$C$2:$J$2000,8,0) -> 0
A9: 8 | B9: PS1 | C9: ELSE=DPS-AFS262 | D9: Cleveland Controls | E9: AFS-262 | F9: DIFFERENTIAL PRESSURE SWITCH, 0.05-2" WC, ADJUSTABLE, SPDT | G9: 1 | H9: =VLOOKUP($C9,'Size DB'!$C$2:$J$2000,6,0) -> 83 | I9: =VLOOKUP($C9,'Size DB'!$C$2:$J$2000,7,0) -> 156 | J9: =VLOOKUP($C9,'Size DB'!$C$2:$J$2000,8,0) -> 0
A10: 9 | B10: M1 | C10: ENCF=AFK300-7P5HP-480V-ST | D10: Continental Fan | E10: AFK300-J2-A181A09 | F10: DIRECT DRIVE PANEL FAN, 7.5 HP, 1750 RPM, 5.5A, 480VAC, 3 PHASE | G10: 1 | H10: =VLOOKUP($C10,'Size DB'!$C$2:$J$2000,6,0) -> 0 | I10: =VLOOKUP($C10,'Size DB'!$C$2:$J$2000,7,0) -> 0 | J10: =VLOOKUP($C10,'Size DB'!$C$2:$J$2000,8,0) -> 0
A11: 10 | B11: FC1, FC2, FC3, FC4, FC5, FC6, FC7, FC8, FC9, FC10, FC11, FC12, FC13, FC14, FC15, FC16, FC17, FC18, FC19, FC20, FC21, FC22, FC23, FC24, FC25, FC26, FC27, FC28, FC29, FC30, FC31, FC32, FC33, FC34, FC35, FC36, FC37, FC38, FC39, FC40, FC41, FC42, FC43, FC44, FC45, FC46, FC47, FC48, FC49, FC50, FC51, FC52, FC53, FC54, FC55, FC56, FC57, FC58, FC59, FC60, FC61, FC62, FC63, FC64, FC65, FC66, FC67, FC68, FC69, FC70, FC71, FC72, FC73, FC74, FC75 | C11: SPFU=690V-40A-BS88 | D11: Eaton Bussmann | E11: 40FE | F11: FUSE 40A, 690VAC, 500VDC, 200kA BREAKING CAPACITY | G11: 75 | H11: =VLOOKUP($C11,'Size DB'!$C$2:$J$2000,6,0) -> 0 | I11: =VLOOKUP($C11,'Size DB'!$C$2:$J$2000,7,0) -> 0 | J11: =VLOOKUP($C11,'Size DB'!$C$2:$J$2000,8,0) -> 0
A12: 11 | B12: M2 | C12: ENCF=FF-8-81-120VAC | D12: Finder Components | E12: 7F.30.8.120.3100 | F12: COOLING FAN, UL TYPE NEMA 3R / IP54, 120 VAC, 1.14 A, 81 CFM | G12: 1 | H12: =VLOOKUP($C12,'Size DB'!$C$2:$J$2000,6,0) -> 0 | I12: =VLOOKUP($C12,'Size DB'!$C$2:$J$2000,7,0) -> 0 | J12: =VLOOKUP($C12,'Size DB'!$C$2:$J$2000,8,0) -> 0
A13: 12 | B13: CPT1 | C13: INPT=SP1000ACP | D13: Hammond | E13: SP1000ACP | F13: CONTROL POWER TRANSFORMER, 1000VA | G13: 1 | H13: =VLOOKUP($C13,'Size DB'!$C$2:$J$2000,6,0) -> 133.35 | I13: =VLOOKUP($C13,'Size DB'!$C$2:$J$2000,7,0) -> 111 | J13: =VLOOKUP($C13,'Size DB'!$C$2:$J$2000,8,0) -> 138.94
... A27: 26 | B27: S1 | C27: SPPB=EMER | D27: NHD Industrial | E27: NLB22-R | F27: EMERGENCY PUSH-BUTTON NC, IP65, 22mm, ILLUMINATED, 120V AC/DC | G27: 1 | H27: =VLOOKUP($C27,'Size DB'!$C$2:$J$2000,6,0) -> 0 | I27: =VLOOKUP($C27,'Size DB'!$C$2:$J$2000,7,0) -> 0 | J27: =VLOOKUP($C27,'Size DB'!$C$2:$J$2000,8,0) -> 0
A28: 27 | B28: N1 | C28: ELPS=24VDC-60W | D28: Phoenix Contact | E28: 2902992 | F28: UNO POWER SUPPLY, 24VDC, 60W | G28: 1 | H28: =VLOOKUP($C28,'Size DB'!$C$2:$J$2000,6,0) -> 35 | I28: =VLOOKUP($C28,'Size DB'!$C$2:$J$2000,7,0) -> 90 | J28: =VLOOKUP($C28,'Size DB'!$C$2:$J$2000,8,0) -> 0
A29: 28 | B29: EP1, EP2, EP3 | C29: ELNW=CON-RJ45 | D29: Rean | E29: RRE8F-Z-011-1 | F29: IP65 RJ45 FEED THROUGH ETHERNET CONNECTOR (FEMALE TO FEMALE) | G29: 3 | H29: =VLOOKUP($C29,'Size DB'!$C$2:$J$2000,6,0) -> 0 | I29: =VLOOKUP($C29,'Size DB'!$C$2:$J$2000,7,0) -> 0 | J29: =VLOOKUP($C29,'Size DB'!$C$2:$J$2000,8,0) -> 0
A30: 29 | B30: TC1, TC2, TC3 | C30: ELSE=TCK-10M-150MM | D30: RPD | E30: RPD-TP-R-05874 | F30: TYPE K THERMOCOUPLE, 6*150mm, 1/2NPT, 10 METER WIRE | G30: 3 | H30: =VLOOKUP($C30,'Size DB'!$C$2:$J$2000,6,0) -> 0 | I30: =VLOOKUP($C30,'Size DB'!$C$2:$J$2000,7,0) -> 0 | J30: =VLOOKUP($C30,'Size DB'!$C$2:$J$2000,8,0) -> 0
A31: 30 | B31: RM1 | C31: SPLD=RM17TU | D31: Schneider Electric | E31: RM17TU00 | F31: RELAY OUTPUT MONITORS, 208-480 VAC | G31: 1 | H31: =VLOOKUP($C31,'Size DB'!$C$2:$J$2000,6,0) -> 17.5 | I31: =VLOOKUP($C31,'Size DB'!$C$2:$J$2000,7,0) -> 90 | J31: =VLOOKUP($C31,'Size DB'!$C$2:$J$2000,8,0) -> 72
A32: 31 | B32: CB1 | C32: SPLD=MMS-3RV2-10A | D32: Siemens | E32: 3RV2011-1JA10 | F32: MANUAL MOTOR PROTECTOR, 7-10A ADJUSTABLE, 600VAC, THERMAL/MAGNETIC TRIP | G32: 1 | H32: =VLOOKUP($C32,'Size DB'!$C$2:$J$2000,6,0) -> 45 | I32: =VLOOKUP($C32,'Size DB'!$C$2:$J$2000,7,0) -> 97 | J32: =VLOOKUP($C32,'Size DB'!$C$2:$J$2000,8,0) -> 97
A33: 32 | B33: CB1 | C33: SPLD=MMS-3RA1921-1DA00 | D33: Siemens | E33: 3RA1921-1DA00 | F33: CONNECTION BRACKET FOR MOTOR STARTER AND CONTACTOR | G33: 1 | H33: =VLOOKUP($C33,'Size DB'!$C$2:$J$2000,6,0) -> 0 | I33: =VLOOKUP($C33,'Size DB'!$C$2:$J$2000,7,0) -> 0 | J33: =VLOOKUP($C33,'Size DB'!$C$2:$J$2000,8,0) -> 0
A34: 33 | B34: CB1 | C34: SPLD=MMS-3RV2901-1E | D34: Siemens | E34: 3RV2901-1E | F34: AUXILIARY CONTACT, 1NO-1NC, 6A | G34: 1 | H34: =VLOOKUP($C34,'Size DB'!$C$2:$J$2000,6,0) -> 0 | I34: =VLOOKUP($C34,'Size DB'!$C$2:$J$2000,7,0) -> 0 | J34: =VLOOKUP($C34,'Size DB'!$C$2:$J$2000,8,0) -> 0
A35: 34 | B35: K2, K3 | C35: SPCO=3RT-12A-4NO | D35: Siemens | E35: 3RT2017-1AF01 | F35: CONTACTOR, 3NO+1NO AUX. CONTACT, 12A, 120VAC | G35: 2 | H35: =VLOOKUP($C35,'Size DB'!$C$2:$J$2000,6,0) -> 45 | I35: =VLOOKUP($C35,'Size DB'!$C$2:$J$2000,7,0) -> 57.5 | J35: =VLOOKUP($C35,'Size DB'!$C$2:$J$2000,8,0) -> 73
A36: 35 | B36: K1 | C36: SPCO=3RT-16A-4NO | D36: Siemens | E36: 3RT2018-1AF01 | F36: CONTACTOR, 3NO+1NO AUX. CONTACT, 16A, 120VAC | G36: 1 | H36: =VLOOKUP($C36,'Size DB'!$C$2:$J$2000,6,0) -> 45 | I36: =VLOOKUP($C36,'Size DB'!$C$2:$J$2000,7,0) -> 57.5 | J36: =VLOOKUP($C36,'Size DB'!$C$2:$J$2000,8,0) -> 73
A37: 36 | B37: DS1 | C37: SPLD=BASE-22003002 | D37: Socomec | E37: 22003002 | F37: DISCONNECT SWITCH, 3POLE, 600V, 25A | G37: 1 | H37: =VLOOKUP($C37,'Size DB'!$C$2:$J$2000,6,0) -> 0 | I37: =VLOOKUP($C37,'Size DB'!$C$2:$J$2000,7,0) -> 0 | J37: =VLOOKUP($C37,'Size DB'!$C$2:$J$2000,8,0) -> 0
A38: 37 | B38: DS1 | C38: SPLD=HA-DM-22993409 | D38: Socomec | E38: 22993409 | F38: DOOR MOUNTING HARDWARE, S0 AND S00 TYPE | G38: 1 | H38: =VLOOKUP($C38,'Size DB'!$C$2:$J$2000,6,0) -> 0 | I38: =VLOOKUP($C38,'Size DB'!$C$2:$J$2000,7,0) -> 0 | J38: =VLOOKUP($C38,'Size DB'!$C$2:$J$2000,8,0) -> 0
A39: 38 | B39: DS1 | C39: SPLD=HA-SOCO | D39: Socomec | E39: 14731111 | F39: ROTARY HANDLE, 2 POSITION, S00 TYPE | G39: 1 | H39: =VLOOKUP($C39,'Size DB'!$C$2:$J$2000,6,0) -> 0 | I39: =VLOOKUP($C39,'Size DB'!$C$2:$J$2000,7,0) -> 0 | J39: =VLOOKUP($C39,'Size DB'!$C$2:$J$2000,8,0) -> 0
A40: 39 | B40: DS1 | C40: SPLD=SHAFT-SOCO | D40: Socomec | E40: 14070532 | F40: SHAFT FOR INTERLOCKING WITH DOOR, 320mm, S0 AND S00 TYPE HANDLES | G40: 1 | H40: =VLOOKUP($C40,'Size DB'!$C$2:$J$2000,6,0) -> 0 | I40: =VLOOKUP($C40,'Size DB'!$C$2:$J$2000,7,0) -> 0 | J40: =VLOOKUP($C40,'Size DB'!$C$2:$J$2000,8,0) -> 0
... A54: 53 | B54: TB1 6, TB3 1, TB3 2, TB3 3, TB3 4, TB3 5, TB3 7, TB3 6, TB5 1, TB5 2, TB5 3, TB5 4, TB5 5, TB5 6, TB6 1, TB6 2, TB6 3, TB6 4, TB6 5, TB6 6, TB6 7, TB6 8, TB6 9, TB3 8, TB3 9, TB3 10, TB3 11, TB3 12, TB3 13, TB1 1, TB1 3, TB1 5, TB1 7, TB1 8, TB1 10, TB1 12, TB1 13, TB1 14, TB2 1, TB2 2, TB2 3, TB2 4, TB1 15, TB1 4, TB1 11, TB2 5, TB1 16, TB2 6, TB1 9, TB1 2, TB1 17, TB6 10, TB6 11 | C54: TEDI=A2C4 | D54: Weidmüller | E54: A2C4 | F54: FEED-THROUGH TERMINAL, PUSH IN, 4mm, 800V, 32A, #10-28 AWG | G54: 53 | H54: =VLOOKUP($C54,'Size DB'!$C$2:$J$2000,6,0) -> 6.1 | I54: =VLOOKUP($C54,'Size DB'!$C$2:$J$2000,7,0) -> 60 | J54: =VLOOKUP($C54,'Size DB'!$C$2:$J$2000,8,0) -> 39.5

Sheet Size DB
C1: PN | D1: MANUFACTURER | E1: MANUFACTURER PART # | F1: DESCRIPTION | G1: Note | H1: W (mm) | I1: H | J1: D | L1: W (in) | M1: H | N1: D
C2: SPCB=SU201M-C13 | D2: ABB | E2: SU201M-C13 | F2: MINIATURE CIRCUIT BREAKER, 230 VAC, 13A, 1 POLE, C-CURVE TRIP | H2: 17.5 | I2: 111 | J2: 0 | L2: =H2/25.4 -> 0.68897638 | M2: =I2/25.4 -> 4.3700787 | N2: =J2/25.4 -> 0
C3: SPCB=SU201M-C4 | D3: ABB | E3: SU201M-C4 | F3: MINIATURE CIRCUIT BREAKER, 230 VAC, 4A, 1 POLE, C-CURVE TRIP | H3: 17.5 | I3: 111 | L3: =H3/25.4 -> 0.68897638 | M3: =I3/25.4 -> 4.3700787 | N3: =J3/25.4 -> 0
C4: ELCO=ACUVIM-AXM-WEB2 | D4: Accuenergy | E4: AXM-WEB2 | F4: MULTIFUNCTION POWER AND ENERGY METER COMMUNICATION MODULE | G4: Accessories | H4: 0 | I4: 0 | L4: =H4/25.4 -> 0 | M4: =I4/25.4 -> 0 | N4: =J4/25.4 -> 0
C5: ELCO=ACUVIM-CL-M-5A-P1V4 | D5: Accuenergy | E5: Acuvim-CL-M-5A-P1V4 | F5: MULTIFUNCTION POWER AND ENERGY METER, 1-5A, 100-415 VAC | H5: 96 | I5: 96 | L5: =H5/25.4 -> 3.7795276 | M5: =I5/25.4 -> 3.7795276 | N5: =J5/25.4 -> 0
C6: INCT=2031-1001 | D6: Accuenergy | E6: AcuCT-2031-1000:5 | F6: SPLIT-CORE CURRENT TRANSFORMER, 1000:5A | H6: 114 | I6: 145 | L6: =H6/25.4 -> 4.488189 | M6: =I6/25.4 -> 5.7086614 | N6: =J6/25.4 -> 0
C7: ELTO=TPC-107WX | D7: Advantech Corp | E7: TPC-107WX-N32YA | F7: TOUCH SCREEN HMI, 7" SCREEN, 2GB RAM, 16GB STORAGE, -30C TO 70C | H7: 205 | I7: 146.92 | L7: =H7/25.4 -> 8.0708661 | M7: =I7/25.4 -> 5.784252 | N7: =J7/25.4 -> 0
C8: ELSE=PS21L-NS11R1-T00 | D8: Carlo Gavazzi | E8: PS21L-NS11R1-T00 | F8: SWITCH LIMIT, ROLLER LEVER, SPST-NO, SPST-NC, 10A | G8: Not plate mount | H8: 0 | I8: 0 | J8: 0 | L8: =H8/25.4 -> 0 | M8: =I8/25.4 -> 0 | N8: =J8/25.4 -> 0
C9: ELSE=DPS-AFS262 | D9: Cleveland Controls | E9: AFS-262 | F9: DIFFERENTIAL PRESSURE SWITCH, 0.05-2" WC, ADJUSTABLE, SPDT | H9: 83 | I9: 156 | L9: =H9/25.4 -> 3.2677165 | M9: =I9/25.4 -> 6.1417323 | N9: =J9/25.4 -> 0
C10: ENCF=AFK300-7P5HP-480V-ST | D10: Continental Fan | E10: AFK300-J2-A181A09 | F10: DIRECT DRIVE PANEL FAN, 7.5 HP, 1750 RPM, 5.5A, 480VAC, 3 PHASE | G10: Not plate mount | H10: 0 | I10: 0 | J10: 0 | L10: =H10/25.4 -> 0 | M10: =I10/25.4 -> 0 | N10: =J10/25.4 -> 0
C11: SPFU=690V-40A-BS88 | D11: Eaton Bussmann | E11: 40FE | F11: FUSE 40A, 690VAC, 500VDC, 200kA BREAKING CAPACITY | G11: Not plate mount | H11: 0 | I11: 0 | J11: 0 | L11: =H11/25.4 -> 0 | M11: =I11/25.4 -> 0 | N11: =J11/25.4 -> 0
C12: ENCF=FF-8-81-120VAC | D12: Finder Components | E12: 7F.30.8.120.3100 | F12: COOLING FAN, UL TYPE NEMA 3R / IP54, 120 VAC, 1.14 A, 81 CFM | G12: Not plate mount | H12: 0 | I12: 0 | J12: 0 | L12: =H12/25.4 -> 0 | M12: =I12/25.4 -> 0 | N12: =J12/25.4 -> 0
C13: INPT=SP1000ACP | D13: Hammond | E13: SP1000ACP | F13: CONTROL POWER TRANSFORMER, 1000VA | H13: 133.35 | I13: 111 | J13: 138.94 | L13: =H13/25.4 -> 5.25 | M13: =I13/25.4 -> 4.3700787 | N13: =J13/25.4 -> 5.4700787
C14: SPCO=DP-600X120-40A-3NO | D14: Hecheng Electric | E14: SA-3P-40A-120V | F14: CONTACTOR, 3 POLES, 40A, 120VAC | H14: 73.66 | I14: 95.25 | J14: 76.2 | L14: =H14/25.4 -> 2.9 | M14: =I14/25.4 -> 3.75 | N14: =J14/25.4 -> 3
C15: ELNW=VPN-IN302 | D15: InHand | E15: IR302 | F15: COMPACT INDUSTRIAL LTE CAT 4 ROUTER WITH 2 ETHERNET PORTS | H15: 25 | I15: 90 | L15: =H15/25.4 -> 0.98425197 | M15: =I15/25.4 -> 3.5433071 | N15: =J15/25.4 -> 0
C16: SPFU=600V-1A | D16: Mersen | E16: ATMR1 | F16: FUSE 1A, 600V, FAST ACTING CLASS CC | G16: Not plate mount | H16: 0 | I16: 0 | J16: 0 | L16: =H16/25.4 -> 0 | M16: =I16/25.4 -> 0 | N16: =J16/25.4 -> 0
C17: SPFU=600V-25A-TD | D17: Mersen | E17: ATQR25 | F17: FUSE 25A, 600V, TIME DELAY CLASS CC | G17: Not plate mount | H17: 0 | I17: 0 | J17: 0 | L17: =H17/25.4 -> 0 | M17: =I17/25.4 -> 0 | N17: =J17/25.4 -> 0
C18: SPFU=600V-3A | D18: Mersen | E18: USCC1 / ATMR3 | F18: FUSE 3A, 600V, FAST ACTING CLASS CC | G18: Not plate mount | H18: 0 | I18: 0 | J18: 0 | L18: =H18/25.4 -> 0 | M18: =I18/25.4 -> 0 | N18: =J18/25.4 -> 0
C19: SPFU=600V-4A-TD | D19: Mersen | E19: ATQR4 | F19: FUSE 4A, 600V, TIME DELAY CLASS CC | G19: Not plate mount | H19: 0 | I19: 0 | J19: 0 | L19: =H19/25.4 -> 0 | M19: =I19/25.4 -> 0 | N19: =J19/25.4 -> 0
C20: SPFU=600V-6A | D20: Mersen | E20: USCC1 / ATMR6 | F20: FUSE 6A, 600V, FAST ACTING CLASS CC | G20: Not plate mount | H20: 0 | I20: 0 | J20: 0 | L20: =H20/25.4 -> 0 | M20: =I20/25.4 -> 0 | N20: =J20/25.4 -> 0
C21: SPFU=HO | D21: Mersen | E21: USCC1 | F21: MODULAR FUSE HOLDER, CLASS CC | H21: 17.5 | I21: 78 | L21: =H21/25.4 -> 0.68897638 | M21: =I21/25.4 -> 3.0708661 | N21: =J21/25.4 -> 0
C22: IDLA=R120AC | D22: NHD Industrial | E22: NLD22-RE | F22: RED PILOT LIGHT, 120 VAC | G22: Not plate mount | H22: 0 | I22: 0 | J22: 0 | L22: =H22/25.4 -> 0 | M22: =I22/25.4 -> 0 | N22: =J22/25.4 -> 0
C23: SPPB=1NC-CB-01 | D23: NHD Industrial | E23: CB-01 | F23: PUSH-BUTTON CONTACT BLOCK, NC, 22mm | G23: Not plate mount | H23: 0 | I23: 0 | J23: 0 | L23: =H23/25.4 -> 0 | M23: =I23/25.4 -> 0 | N23: =J23/25.4 -> 0
C24: SPSS=02 | D24: NHD Industrial | E24: NSS22-S210B | F24: SELECTOR SWITCH, 2 POS | G24: Not plate mount | H24: 0 | I24: 0 | J24: 0 | L24: =H24/25.4 -> 0 | M24: =I24/25.4 -> 0 | N24: =J24/25.4 -> 0
C25: IDLA=Y120AC | D25: NHD Industrial | E25: NLD22-YE | F25: YELLOW PILOT LIGHT, 120 VAC | G25: Not plate mount | H25: 0 | I25: 0 | J25: 0 | L25: =H25/25.4 -> 0 | M25: =I25/25.4 -> 0 | N25: =J25/25.4 -> 0
C26: IDLA=G120AC | D26: NHD Industrial | E26: NLD22-GE | F26: GREEN PILOT LIGHT, 120 VAC | G26: Not plate mount | H26: 0 | I26: 0 | J26: 0 | L26: =H26/25.4 -> 0 | M26: =I26/25.4 -> 0 | N26: =J26/25.4 -> 0
C27: SPPB=EMER | D27: NHD Industrial | E27: NLB22-R | F27: EMERGENCY PUSH-BUTTON NC, IP65, 22mm, ILLUMINATED, 120V AC/DC | G27: Not plate mount | H27: 0 | I27: 0 | J27: 0 | L27: =H27/25.4 -> 0 | M27: =I27/25.4 -> 0 | N27: =J27/25.4 -> 0
C28: ELPS=24VDC-60W | D28: Phoenix Contact | E28: 2902992 | F28: UNO POWER SUPPLY, 24VDC, 60W | H28: 35 | I28: 90 | L28: =H28/25.4 -> 1.3779528 | M28: =I28/25.4 -> 3.5433071 | N28: =J28/25.4 -> 0
C29: ELNW=CON-RJ45 | D29: Rean | E29: RRE8F-Z-011-1 | F29: IP65 RJ45 FEED THROUGH ETHERNET CONNECTOR (FEMALE TO FEMALE) | G29: Not plate mount | H29: 0 | I29: 0 | J29: 0 | L29: =H29/25.4 -> 0 | M29: =I29/25.4 -> 0 | N29: =J29/25.4 -> 0
C30: ELSE=TCK-10M-150MM | D30: RPD | E30: RPD-TP-R-05874 | F30: TYPE K THERMOCOUPLE, 6*150mm, 1/2NPT, 10 METER WIRE | G30: Not plate mount | H30: 0 | I30: 0 | J30: 0 | L30: =H30/25.4 -> 0 | M30: =I30/25.4 -> 0 | N30: =J30/25.4 -> 0
C31: SPLD=RM17TU | D31: Schneider Electric | E31: RM17TU00 | F31: RELAY OUTPUT MONITORS, 208-480 VAC | H31: 17.5 | I31: 90 | J31: 72 | L31: =H31/25.4 -> 0.68897638 | M31: =I31/25.4 -> 3.5433071 | N31: =J31/25.4 -> 2.8346457
C32: SPLD=MMS-3RV2-10A | D32: Siemens | E32: 3RV2011-1JA10 | F32: MANUAL MOTOR PROTECTOR, 7-10A ADJUSTABLE, 600VAC, THERMAL/MAGNETIC TRIP | H32: 45 | I32: 97 | J32: 97 | L32: =H32/25.4 -> 1.7716535 | M32: =I32/25.4 -> 3.8188976 | N32: =J32/25.4 -> 3.8188976
C33: SPLD=MMS-3RA1921-1DA00 | D33: Siemens | E33: 3RA1921-1DA00 | F33: CONNECTION BRACKET FOR MOTOR STARTER AND CONTACTOR | G33: Accessories | H33: 0 | I33: 0 | J33: 0 | L33: =H33/25.4 -> 0 | M33: =I33/25.4 -> 0 | N33: =J33/25.4 -> 0
C34: SPLD=MMS-3RV2901-1E | D34: Siemens | E34: 3RV2901-1E | F34: AUXILIARY CONTACT, 1NO-1NC, 6A | G34: Accessories | H34: 0 | I34: 0 | J34: 0 | L34: =H34/25.4 -> 0 | M34: =I34/25.4 -> 0 | N34: =J34/25.4 -> 0
C35: SPCO=3RT-12A-4NO | D35: Siemens | E35: 3RT2017-1AF01 | F35: CONTACTOR, 3NO+1NO AUX. CONTACT, 12A, 120VAC | H35: 45 | I35: 57.5 | J35: 73 | L35: =H35/25.4 -> 1.7716535 | M35: =I35/25.4 -> 2.2637795 | N35: =J35/25.4 -> 2.8740157
C36: SPCO=3RT-16A-4NO | D36: Siemens | E36: 3RT2018-1AF01 | F36: CONTACTOR, 3NO+1NO AUX. CONTACT, 16A, 120VAC | H36: 45 | I36: 57.5 | J36: 73 | L36: =H36/25.4 -> 1.7716535 | M36: =I36/25.4 -> 2.2637795 | N36: =J36/25.4 -> 2.8740157
C37: SPLD=BASE-22003002 | D37: Socomec | E37: 22003002 | F37: DISCONNECT SWITCH, 3POLE, 600V, 25A | G37: Not plate mount | H37: 0 | I37: 0 | J37: 0 | L37: =H37/25.4 -> 0 | M37: =I37/25.4 -> 0 | N37: =J37/25.4 -> 0
C38: SPLD=HA-DM-22993409 | D38: Socomec | E38: 22993409 | F38: DOOR MOUNTING HARDWARE, S0 AND S00 TYPE | G38: Accessories | H38: 0 | I38: 0 | J38: 0 | L38: =H38/25.4 -> 0 | M38: =I38/25.4 -> 0 | N38: =J38/25.4 -> 0
C39: SPLD=HA-SOCO | D39: Socomec | E39: 14731111 | F39: ROTARY HANDLE, 2 POSITION, S00 TYPE | G39: Accessories | H39: 0 | I39: 0 | J39: 0 | L39: =H39/25.4 -> 0 | M39: =I39/25.4 -> 0 | N39: =J39/25.4 -> 0
C40: SPLD=SHAFT-SOCO | D40: Socomec | E40: 14070532 | F40: SHAFT FOR INTERLOCKING WITH DOOR, 320mm, S0 AND S00 TYPE HANDLES | G40: Accessories | H40: 0 | I40: 0 | J40: 0 | L40: =H40/25.4 -> 0 | M40: =I40/25.4 -> 0 | N40: =J40/25.4 -> 0
...
